---
title: Promise
date: 2021-08-18 22:31:02
permalink: /pages/abdd8e/
categories:
  - 前端
tags:
  - 《ES6 教程》笔记
---
### 1. Promise 的含义
Promise对象有以下两个特点。  

（1）对象的状态不受外界影响。Promise对象代表一个异步操作，有三种状态：pending（进行中）、fulfilled（已成功）和rejected（已失败）。只有异步操作的结果，可以决定当前是哪一种状态，任何其他操作都无法改变这个状态。这也是Promise这个名字的由来，它的英语意思就是“承诺”，表示其他手段无法改变。  

（2）一旦状态改变，就不会再变，任何时候都可以得到这个结果。Promise对象的状态改变，只有两种可能：从pending变为fulfilled和从pending变为rejected。只要这两种情况发生，状态就凝固了，不会再变了，会一直保持这个结果，这时就称为 resolved（已定型）。如果改变已经发生了，你再对Promise对象添加回调函数，也会立即得到这个结果。这与事件（Event）完全不同，事件的特点是，如果你错过了它，再去监听，是得不到结果的。  

### 2. Promise.prototype.then()
```
new Promise((resolve, reject) => {
  resolve(1);
  console.log(2);
}).then(r => {
  console.log(r);
});
// 2
// 1
```
上面代码中，调用resolve(1)以后，后面的console.log(2)还是会执行，并且会首先打印出来。这是因为立即 resolved 的 Promise 是在本轮事件循环的末尾执行，总是晚于本轮循环的同步任务。  

一般来说，调用resolve或reject以后，Promise 的使命就完成了，后继操作应该放到then方法里面，而不应该直接写在resolve或reject的后面。所以，最好在它们前面加上return语句，这样就不会有意外。  
```
new Promise((resolve, reject) => {
  return resolve(1);
  // 后面的语句不会执行
  console.log(2);
})
```

### 3. Promise.prototype.catch()
```
// 写法一
const promise = new Promise(function(resolve, reject) {
  try {
    throw new Error('test');
  } catch(e) {
    reject(e);
  }
});
promise.catch(function(error) {
  console.log(error);
});

// 写法二
const promise = new Promise(function(resolve, reject) {
  reject(new Error('test'));
});
promise.catch(function(error) {
  console.log(error);
});
```

比较上面两种写法，可以发现reject()方法的作用，等同于抛出错误。  

如果 Promise 状态已经变成resolved，再抛出错误是无效的。  
```
const promise = new Promise(function(resolve, reject) {
  resolve('ok');
  throw new Error('test');
});
promise
  .then(function(value) { console.log(value) })
  .catch(function(error) { console.log(error) });
// ok
```

上面代码中，Promise 在resolve语句后面，再抛出错误，不会被捕获，等于没有抛出。因为 Promise 的状态一旦改变，就永久保持该状态，不会再变了。  

一般来说，不要在then()方法里面定义 Reject 状态的回调函数（即then的第二个参数），总是使用catch方法。
```
// bad
promise
  .then(function(data) {
    // success
  }, function(err) {
    // error
  });

// good
promise
  .then(function(data) { //cb
    // success
  })
  .catch(function(err) {
    // error
  });
```
上面代码中，第二种写法要好于第一种写法，理由是第二种写法可以捕获前面then方法执行中的错误，也更接近同步的写法（try/catch）。因此，建议总是使用catch()方法，而不使用then()方法的第二个参数。

### 4. Promise.prototype.finally()
finally()方法用于指定不管 Promise 对象最后状态如何，都会执行的操作。该方法是 ES2018 引入标准的。
```
promise
.then(result => {···})
.catch(error => {···})
.finally(() => {···});
```
上面代码中，不管promise最后的状态，在执行完then或catch指定的回调函数以后，都会执行finally方法指定的回调函数。  
### 5. Promise.all()
```
const p = Promise.all([p1, p2, p3]);
```
p的状态由p1、p2、p3决定，分成两种情况。  

（1）只有p1、p2、p3的状态都变成fulfilled，p的状态才会变成fulfilled，此时p1、p2、p3的返回值组成一个数组，传递给p的回调函数。  

（2）只要p1、p2、p3之中有一个被rejected，p的状态就变成rejected，此时第一个被reject的实例的返回值，会传递给p的回调函数。  

注意，如果作为参数的 Promise 实例，自己定义了catch方法，那么它一旦被rejected，并不会触发Promise.all()的catch方法。  

```
const p1 = new Promise((resolve, reject) => {
  resolve('hello');
})
.then(result => result)
.catch(e => e);

const p2 = new Promise((resolve, reject) => {
  throw new Error('报错了');
})
.then(result => result)
.catch(e => e);

Promise.all([p1, p2])
.then(result => console.log(result))
.catch(e => console.log(e));
// ["hello", Error: 报错了]
```
上面代码中，p1会resolved，p2首先会rejected，但是p2有自己的catch方法，该方法返回的是一个新的 Promise 实例，p2指向的实际上是这个实例。该实例执行完catch方法后，也会变成resolved，导致Promise.all()方法参数里面的两个实例都会resolved，因此会调用then方法指定的回调函数，而不会调用catch方法指定的回调函数。  

如果p2没有自己的catch方法，就会调用Promise.all()的catch方法。
```
const p1 = new Promise((resolve, reject) => {
  resolve('hello');
})
.then(result => result);

const p2 = new Promise((resolve, reject) => {
  throw new Error('报错了');
})
.then(result => result);

Promise.all([p1, p2])
.then(result => console.log(result))
.catch(e => console.log(e));
// Error: 报错了
```

### 6. Promise.race() 
```
const p = Promise.race([p1, p2, p3]);
```
上面代码中，只要p1、p2、p3之中有一个实例率先改变状态，p的状态就跟着改变。那个率先改变的 Promise 实例的返回值，就传递给p的回调函数。  

```
const p = Promise.race([
  fetch('/resource-that-may-take-a-while'),
  new Promise(function (resolve, reject) {
    setTimeout(() => reject(new Error('request timeout')), 5000)
  })
]);

p
.then(console.log)
.catch(console.error);
```
上面代码中，如果 5 秒之内fetch方法无法返回结果，变量p的状态就会变为rejected，从而触发catch方法指定的回调函数。

### 7. Promise.allSettled()
Promise.allSettled()方法接受一个数组作为参数，数组的每个成员都是一个 Promise 对象，并返回一个新的 Promise 对象。只有等到参数数组的所有 Promise 对象都发生状态变更（不管是fulfilled还是rejected），返回的 Promise 对象才会发生状态变更。  

```
const resolved = Promise.resolve(42);
const rejected = Promise.reject(-1);

const allSettledPromise = Promise.allSettled([resolved, rejected]);

allSettledPromise.then(function (results) {
  console.log(results);
});
// [
//    { status: 'fulfilled', value: 42 },
//    { status: 'rejected', reason: -1 }
// ]
```
上面代码中，Promise.allSettled()的返回值allSettledPromise，状态只可能变成fulfilled。它的回调函数接收到的参数是数组results。该数组的每个成员都是一个对象，对应传入Promise.allSettled()的数组里面的两个 Promise 对象。  

results的每个成员是一个对象，对象的格式是固定的，对应异步操作的结果。  
```
const promises = [ fetch('index.html'), fetch('https://does-not-exist/') ];
const results = await Promise.allSettled(promises);

// 过滤出成功的请求
const successfulPromises = results.filter(p => p.status === 'fulfilled');

// 过滤出失败的请求，并输出原因
const errors = results
  .filter(p => p.status === 'rejected')
  .map(p => p.reason);
```
### 8. Promise.any()
```
Promise.any([
  fetch('https://v8.dev/').then(() => 'home'),
  fetch('https://v8.dev/blog').then(() => 'blog'),
  fetch('https://v8.dev/docs').then(() => 'docs')
]).then((first) => {  // 只要有一个 fetch() 请求成功
  console.log(first);
}).catch((error) => { // 所有三个 fetch() 全部请求失败
  console.log(error);
});
```

Promise.any()抛出的错误，不是一个一般的 Error 错误对象，而是一个 AggregateError 实例。它相当于一个数组，每个成员对应一个被rejected的操作所抛出的错误。下面是 AggregateError 的实现示例。  
```
// new AggregateError() extends Array

const err = new AggregateError();
err.push(new Error("first error"));
err.push(new Error("second error"));
// ...
throw err;
```

### 9. Promise.resolve()
有时需要将现有对象转为 Promise 对象，Promise.resolve()方法就起到这个作用。  
```
const jsPromise = Promise.resolve($.ajax('/whatever.json'));
```
Promise.resolve()方法的参数分成四种情况。  
（1）参数是一个 Promise 实例  
如果参数是 Promise 实例，那么Promise.resolve将不做任何修改、原封不动地返回这个实例。  
（2）参数是一个thenable对象  
thenable对象指的是具有then方法的对象，比如下面这个对象。
```
let thenable = {
  then: function(resolve, reject) {
    resolve(42);
  }
};
```
Promise.resolve()方法会将这个对象转为 Promise 对象，然后就立即执行thenable对象的then()方法。  
```
let thenable = {
  then: function(resolve, reject) {
    resolve(42);
  }
};

let p1 = Promise.resolve(thenable);
p1.then(function (value) {
  console.log(value);  // 42
});
```
（3）参数不是具有then()方法的对象，或根本就不是对象  

如果参数是一个原始值，或者是一个不具有then()方法的对象，则Promise.resolve()方法返回一个新的 Promise 对象，状态为resolved。

```
const p = Promise.resolve('Hello');

p.then(function (s) {
  console.log(s)
});
// Hello
```
（4）不带有任何参数  
Promise.resolve()方法允许调用时不带参数，直接返回一个resolved状态的 Promise 对象。  

所以，如果希望得到一个 Promise 对象，比较方便的方法就是直接调用Promise.resolve()方法。  
```
const p = Promise.resolve();

p.then(function () {
  // ...
});
```
上面代码的变量p就是一个 Promise 对象。

需要注意的是，立即resolve()的 Promise 对象，是在本轮“事件循环”（event loop）的结束时执行，而不是在下一轮“事件循环”的开始时。  
```
setTimeout(function () {
  console.log('three');
}, 0);

Promise.resolve().then(function () {
  console.log('two');
});

console.log('one');

// one
// two
// three
```
上面代码中，setTimeout(fn, 0)在下一轮“事件循环”开始时执行，Promise.resolve()在本轮“事件循环”结束时执行，console.log('one')则是立即执行，因此最先输出。  

### 10. Promise.reject()
Promise.reject()方法的参数，会原封不动地作为reject的理由，变成后续方法的参数。
```
Promise.reject('出错了')
.catch(e => {
  console.log(e === '出错了')
})
// true
```
上面代码中，Promise.reject()方法的参数是一个字符串，后面catch()方法的参数e就是这个字符串。   

